#VRML_SIM R2023b utf8

EXTERNPROTO "https://raw.githubusercontent.com/cyberbotics/webots/R2023b/projects/objects/backgrounds/protos/TexturedBackground.proto"
EXTERNPROTO "https://raw.githubusercontent.com/cyberbotics/webots/R2023b/projects/objects/backgrounds/protos/TexturedBackgroundLight.proto"
EXTERNPROTO "https://raw.githubusercontent.com/cyberbotics/webots/R2023b/projects/objects/floors/protos/RectangleArena.proto"

WorldInfo {
}
Viewpoint {
  orientation -0.5773502691896258 0.5773502691896258 0.5773502691896258 2.0944
  position 0.000603297906590224 1.54916974503206e-05 2.0271706250150547
}
TexturedBackground {
}
TexturedBackgroundLight {
}
RectangleArena {
}
Robot {
  children [
    DEF Body Pose {
      translation 0 0 0.0415
      children [
        Shape {
          appearance PBRAppearance {
            roughness 1
          }
          geometry Cylinder {
            height 0.08
            radius 0.045
          }
        }
      ]
    }
    HingeJoint {
      jointParameters HingeJointParameters {
        anchor 0.045 0 0.025
      }
      device [
        RotationalMotor {
          name "motor_1"
        }
        PositionSensor {
          name "ps_1"
        }
      ]
      endPoint Solid {
        translation 0.045 0 0.025
        rotation 0 1 0 1.57
        children [
          DEF wheel Shape {
            appearance PBRAppearance {
              baseColor 1 0 0
              roughness 1
              metalness 0
            }
            geometry Cylinder {
              height 0.01
              radius 0.025
            }
          }
        ]
        boundingObject USE wheel
        physics DEF wheel_physics Physics {
        }
      }
    }
    HingeJoint {
      jointParameters HingeJointParameters {
        anchor -0.045 0 0.025
      }
      device [
        RotationalMotor {
          name "motor_2"
        }
        PositionSensor {
          name "ps_2"
        }
      ]
      endPoint Solid {
        translation -0.045 0 0.025
        rotation 0 1 0 1.57
        children [
          USE wheel
        ]
        name "solid(1)"
        boundingObject USE wheel
        physics USE wheel_physics
      }
    }
  ]
  boundingObject USE Body
  physics Physics {
  }
  controller "drive_controller_2"
}
